This occurred once, not repeated; assertion message made more explicit in test:

pypy3 run-test-pre: PYTHONHASHSEED='1032157503'
pypy3 run-test: commands[0] | nosetests
[{'type': 'correct'}, {'type': 'incorrect'}]{'type': 'correct'}{'type': 'incorrect'}correctincorrect..ABOUT TO RAISE : walking {'': {'Key': ''}}, k=, v={'Key': ''}
................E.......................................................
======================================================================
ERROR: Given a walkable location, view that location.
----------------------------------------------------------------------
Traceback (most recent call last):
  File "/home/alain/src/dpath-python/.tox/pypy3/site-packages/nose/case.py", line 198, in runTest
    self.test(*self.arg)
  File "/home/alain/src/dpath-python/tests/test_segments.py", line 351, in test_view
    def test_view(walkable):
  File "/home/alain/src/dpath-python/.tox/pypy3/site-packages/hypothesis/core.py", line 1169, in wrapped_test
    raise the_error_hypothesis_found
  File "/home/alain/src/dpath-python/tests/test_segments.py", line 359, in test_view
    assert api.get(view, segments) == api.get(node, segments)
  File "/home/alain/src/dpath-python/dpath/segments.py", line 86, in get
    current = current[segment]
KeyError: b'[\x00]'
-------------------- >> begin captured stdout << ---------------------
Falsifying example: test_view(
    walkable=({b'[\x00]': False}, ((b'[\x00]',), False)),
)

--------------------- >> end captured stdout << ----------------------
